Using TensorFlow backend.
2020-03-01 06:45:31.702273: I tensorflow/core/platform/cpu_feature_guard.cc:137] Your CPU supports instructions that this TensorFlow binary was not compiled to use: SSE4.1 SSE4.2 AVX AVX2 AVX512F FMA
/usr/local/lib/python2.7/dist-packages/keras/engine/saving.py:327: UserWarning: Error in loading the saved optimizer state. As a result, your model is starting with a freshly initialized optimizer.
  warnings.warn('Error in loading the saved optimizer '
ERROR:root:Unexpected exception in handler
Traceback (most recent call last):
  File "../../gen-py/social_network/MediaFilterService.py", line 109, in process_UploadMedia
    result.success = self._handler.UploadMedia(args.req_id, args.media_types, args.medium, args.carrier)
  File "MediaFilterService.py", line 91, in UploadMedia
    _return = self._predict(base64_images, ImageSize)
  File "MediaFilterService.py", line 67, in _predict
    images.append(self._load_base64_image(img, image_size))
  File "MediaFilterService.py", line 38, in _load_base64_image
    img_str = base64.b64decode(base64_str)
  File "/usr/lib/python2.7/base64.py", line 78, in b64decode
    raise TypeError(msg)
TypeError: Incorrect padding
ERROR:root:Unexpected exception in handler
Traceback (most recent call last):
  File "../../gen-py/social_network/MediaFilterService.py", line 109, in process_UploadMedia
    result.success = self._handler.UploadMedia(args.req_id, args.media_types, args.medium, args.carrier)
  File "MediaFilterService.py", line 91, in UploadMedia
    _return = self._predict(base64_images, ImageSize)
  File "MediaFilterService.py", line 67, in _predict
    images.append(self._load_base64_image(img, image_size))
  File "MediaFilterService.py", line 38, in _load_base64_image
    img_str = base64.b64decode(base64_str)
  File "/usr/lib/python2.7/base64.py", line 78, in b64decode
    raise TypeError(msg)
TypeError: Incorrect padding
ERROR:root:Unexpected exception in handler
Traceback (most recent call last):
  File "../../gen-py/social_network/MediaFilterService.py", line 109, in process_UploadMedia
    result.success = self._handler.UploadMedia(args.req_id, args.media_types, args.medium, args.carrier)
  File "MediaFilterService.py", line 91, in UploadMedia
    _return = self._predict(base64_images, ImageSize)
  File "MediaFilterService.py", line 67, in _predict
    images.append(self._load_base64_image(img, image_size))
  File "MediaFilterService.py", line 44, in _load_base64_image
    image = image.convert('RGB')
  File "/usr/local/lib/python2.7/dist-packages/PIL/Image.py", line 930, in convert
    self.load()
  File "/usr/local/lib/python2.7/dist-packages/PIL/ImageFile.py", line 272, in load
    raise_ioerror(err_code)
  File "/usr/local/lib/python2.7/dist-packages/PIL/ImageFile.py", line 59, in raise_ioerror
    raise IOError(message + " when reading image file")
IOError: broken data stream when reading image file
ERROR:root:Unexpected exception in handler
Traceback (most recent call last):
  File "../../gen-py/social_network/MediaFilterService.py", line 109, in process_UploadMedia
    result.success = self._handler.UploadMedia(args.req_id, args.media_types, args.medium, args.carrier)
  File "MediaFilterService.py", line 91, in UploadMedia
    _return = self._predict(base64_images, ImageSize)
  File "MediaFilterService.py", line 67, in _predict
    images.append(self._load_base64_image(img, image_size))
  File "MediaFilterService.py", line 42, in _load_base64_image
    image = Image.open(tempBuff)
  File "/usr/local/lib/python2.7/dist-packages/PIL/Image.py", line 2818, in open
    raise IOError("cannot identify image file %r" % (filename if filename else fp))
IOError: cannot identify image file <StringIO.StringIO instance at 0x7f262c08bc30>
ERROR:root:Unexpected exception in handler
Traceback (most recent call last):
  File "../../gen-py/social_network/MediaFilterService.py", line 109, in process_UploadMedia
    result.success = self._handler.UploadMedia(args.req_id, args.media_types, args.medium, args.carrier)
  File "MediaFilterService.py", line 91, in UploadMedia
    _return = self._predict(base64_images, ImageSize)
  File "MediaFilterService.py", line 67, in _predict
    images.append(self._load_base64_image(img, image_size))
  File "MediaFilterService.py", line 42, in _load_base64_image
    image = Image.open(tempBuff)
  File "/usr/local/lib/python2.7/dist-packages/PIL/Image.py", line 2818, in open
    raise IOError("cannot identify image file %r" % (filename if filename else fp))
IOError: cannot identify image file <StringIO.StringIO instance at 0x7f27f0290910>
ERROR:root:Unexpected exception in handler
Traceback (most recent call last):
  File "../../gen-py/social_network/MediaFilterService.py", line 109, in process_UploadMedia
    result.success = self._handler.UploadMedia(args.req_id, args.media_types, args.medium, args.carrier)
  File "MediaFilterService.py", line 91, in UploadMedia
    _return = self._predict(base64_images, ImageSize)
  File "MediaFilterService.py", line 67, in _predict
    images.append(self._load_base64_image(img, image_size))
  File "MediaFilterService.py", line 38, in _load_base64_image
    img_str = base64.b64decode(base64_str)
  File "/usr/lib/python2.7/base64.py", line 78, in b64decode
    raise TypeError(msg)
TypeError: Incorrect padding
ERROR:root:Unexpected exception in handler
Traceback (most recent call last):
  File "../../gen-py/social_network/MediaFilterService.py", line 109, in process_UploadMedia
    result.success = self._handler.UploadMedia(args.req_id, args.media_types, args.medium, args.carrier)
  File "MediaFilterService.py", line 91, in UploadMedia
    _return = self._predict(base64_images, ImageSize)
  File "MediaFilterService.py", line 67, in _predict
    images.append(self._load_base64_image(img, image_size))
  File "MediaFilterService.py", line 42, in _load_base64_image
    image = Image.open(tempBuff)
  File "/usr/local/lib/python2.7/dist-packages/PIL/Image.py", line 2818, in open
    raise IOError("cannot identify image file %r" % (filename if filename else fp))
IOError: cannot identify image file <StringIO.StringIO instance at 0x7f262c04ad70>
ERROR:root:Unexpected exception in handler
Traceback (most recent call last):
  File "../../gen-py/social_network/MediaFilterService.py", line 109, in process_UploadMedia
    result.success = self._handler.UploadMedia(args.req_id, args.media_types, args.medium, args.carrier)
  File "MediaFilterService.py", line 91, in UploadMedia
    _return = self._predict(base64_images, ImageSize)
  File "MediaFilterService.py", line 67, in _predict
    images.append(self._load_base64_image(img, image_size))
  File "MediaFilterService.py", line 38, in _load_base64_image
    img_str = base64.b64decode(base64_str)
  File "/usr/lib/python2.7/base64.py", line 78, in b64decode
    raise TypeError(msg)
TypeError: Incorrect padding
ERROR:root:Unexpected exception in handler
Traceback (most recent call last):
  File "../../gen-py/social_network/MediaFilterService.py", line 109, in process_UploadMedia
    result.success = self._handler.UploadMedia(args.req_id, args.media_types, args.medium, args.carrier)
  File "MediaFilterService.py", line 91, in UploadMedia
    _return = self._predict(base64_images, ImageSize)
  File "MediaFilterService.py", line 67, in _predict
    images.append(self._load_base64_image(img, image_size))
  File "MediaFilterService.py", line 38, in _load_base64_image
    img_str = base64.b64decode(base64_str)
  File "/usr/lib/python2.7/base64.py", line 78, in b64decode
    raise TypeError(msg)
TypeError: Incorrect padding
ERROR:root:Unexpected exception in handler
Traceback (most recent call last):
  File "../../gen-py/social_network/MediaFilterService.py", line 109, in process_UploadMedia
    result.success = self._handler.UploadMedia(args.req_id, args.media_types, args.medium, args.carrier)
  File "MediaFilterService.py", line 91, in UploadMedia
    _return = self._predict(base64_images, ImageSize)
  File "MediaFilterService.py", line 67, in _predict
    images.append(self._load_base64_image(img, image_size))
  File "MediaFilterService.py", line 45, in _load_base64_image
    image = image.resize(image_size)
  File "/usr/local/lib/python2.7/dist-packages/PIL/Image.py", line 1886, in resize
    self.load()
  File "/usr/local/lib/python2.7/dist-packages/PIL/ImageFile.py", line 272, in load
    raise_ioerror(err_code)
  File "/usr/local/lib/python2.7/dist-packages/PIL/ImageFile.py", line 59, in raise_ioerror
    raise IOError(message + " when reading image file")
IOError: broken data stream when reading image file
ERROR:root:Unexpected exception in handler
Traceback (most recent call last):
  File "../../gen-py/social_network/MediaFilterService.py", line 109, in process_UploadMedia
    result.success = self._handler.UploadMedia(args.req_id, args.media_types, args.medium, args.carrier)
  File "MediaFilterService.py", line 91, in UploadMedia
    _return = self._predict(base64_images, ImageSize)
  File "MediaFilterService.py", line 67, in _predict
    images.append(self._load_base64_image(img, image_size))
  File "MediaFilterService.py", line 38, in _load_base64_image
    img_str = base64.b64decode(base64_str)
  File "/usr/lib/python2.7/base64.py", line 78, in b64decode
    raise TypeError(msg)
TypeError: Incorrect padding
ERROR:root:Unexpected exception in handler
Traceback (most recent call last):
  File "../../gen-py/social_network/MediaFilterService.py", line 109, in process_UploadMedia
    result.success = self._handler.UploadMedia(args.req_id, args.media_types, args.medium, args.carrier)
  File "MediaFilterService.py", line 91, in UploadMedia
    _return = self._predict(base64_images, ImageSize)
  File "MediaFilterService.py", line 67, in _predict
    images.append(self._load_base64_image(img, image_size))
  File "MediaFilterService.py", line 45, in _load_base64_image
    image = image.resize(image_size)
  File "/usr/local/lib/python2.7/dist-packages/PIL/Image.py", line 1886, in resize
    self.load()
  File "/usr/local/lib/python2.7/dist-packages/PIL/ImageFile.py", line 272, in load
    raise_ioerror(err_code)
  File "/usr/local/lib/python2.7/dist-packages/PIL/ImageFile.py", line 59, in raise_ioerror
    raise IOError(message + " when reading image file")
IOError: broken data stream when reading image file
ERROR:root:Unexpected exception in handler
Traceback (most recent call last):
  File "../../gen-py/social_network/MediaFilterService.py", line 109, in process_UploadMedia
    result.success = self._handler.UploadMedia(args.req_id, args.media_types, args.medium, args.carrier)
  File "MediaFilterService.py", line 91, in UploadMedia
    _return = self._predict(base64_images, ImageSize)
  File "MediaFilterService.py", line 67, in _predict
    images.append(self._load_base64_image(img, image_size))
  File "MediaFilterService.py", line 38, in _load_base64_image
    img_str = base64.b64decode(base64_str)
  File "/usr/lib/python2.7/base64.py", line 78, in b64decode
    raise TypeError(msg)
TypeError: Incorrect padding
ERROR:root:Unexpected exception in handler
Traceback (most recent call last):
  File "../../gen-py/social_network/MediaFilterService.py", line 109, in process_UploadMedia
    result.success = self._handler.UploadMedia(args.req_id, args.media_types, args.medium, args.carrier)
  File "MediaFilterService.py", line 91, in UploadMedia
    _return = self._predict(base64_images, ImageSize)
  File "MediaFilterService.py", line 67, in _predict
    images.append(self._load_base64_image(img, image_size))
  File "MediaFilterService.py", line 38, in _load_base64_image
    img_str = base64.b64decode(base64_str)
  File "/usr/lib/python2.7/base64.py", line 78, in b64decode
    raise TypeError(msg)
TypeError: Incorrect padding
ERROR:root:Unexpected exception in handler
Traceback (most recent call last):
  File "../../gen-py/social_network/MediaFilterService.py", line 109, in process_UploadMedia
    result.success = self._handler.UploadMedia(args.req_id, args.media_types, args.medium, args.carrier)
  File "MediaFilterService.py", line 91, in UploadMedia
    _return = self._predict(base64_images, ImageSize)
  File "MediaFilterService.py", line 67, in _predict
    images.append(self._load_base64_image(img, image_size))
  File "MediaFilterService.py", line 38, in _load_base64_image
    img_str = base64.b64decode(base64_str)
  File "/usr/lib/python2.7/base64.py", line 78, in b64decode
    raise TypeError(msg)
TypeError: Incorrect padding
ERROR:root:Unexpected exception in handler
Traceback (most recent call last):
  File "../../gen-py/social_network/MediaFilterService.py", line 109, in process_UploadMedia
    result.success = self._handler.UploadMedia(args.req_id, args.media_types, args.medium, args.carrier)
  File "MediaFilterService.py", line 91, in UploadMedia
    _return = self._predict(base64_images, ImageSize)
  File "MediaFilterService.py", line 67, in _predict
    images.append(self._load_base64_image(img, image_size))
  File "MediaFilterService.py", line 38, in _load_base64_image
    img_str = base64.b64decode(base64_str)
  File "/usr/lib/python2.7/base64.py", line 78, in b64decode
    raise TypeError(msg)
TypeError: Incorrect padding
ERROR:root:Unexpected exception in handler
Traceback (most recent call last):
  File "../../gen-py/social_network/MediaFilterService.py", line 109, in process_UploadMedia
    result.success = self._handler.UploadMedia(args.req_id, args.media_types, args.medium, args.carrier)
  File "MediaFilterService.py", line 91, in UploadMedia
    _return = self._predict(base64_images, ImageSize)
  File "MediaFilterService.py", line 67, in _predict
    images.append(self._load_base64_image(img, image_size))
  File "MediaFilterService.py", line 42, in _load_base64_image
    image = Image.open(tempBuff)
  File "/usr/local/lib/python2.7/dist-packages/PIL/Image.py", line 2818, in open
    raise IOError("cannot identify image file %r" % (filename if filename else fp))
IOError: cannot identify image file <StringIO.StringIO instance at 0x7f262c014fa0>
ERROR:root:Unexpected exception in handler
Traceback (most recent call last):
  File "../../gen-py/social_network/MediaFilterService.py", line 109, in process_UploadMedia
    result.success = self._handler.UploadMedia(args.req_id, args.media_types, args.medium, args.carrier)
  File "MediaFilterService.py", line 91, in UploadMedia
    _return = self._predict(base64_images, ImageSize)
  File "MediaFilterService.py", line 67, in _predict
    images.append(self._load_base64_image(img, image_size))
  File "MediaFilterService.py", line 44, in _load_base64_image
    image = image.convert('RGB')
  File "/usr/local/lib/python2.7/dist-packages/PIL/Image.py", line 930, in convert
    self.load()
  File "/usr/local/lib/python2.7/dist-packages/PIL/ImageFile.py", line 272, in load
    raise_ioerror(err_code)
  File "/usr/local/lib/python2.7/dist-packages/PIL/ImageFile.py", line 59, in raise_ioerror
    raise IOError(message + " when reading image file")
IOError: broken data stream when reading image file
ERROR:root:Unexpected exception in handler
Traceback (most recent call last):
  File "../../gen-py/social_network/MediaFilterService.py", line 109, in process_UploadMedia
    result.success = self._handler.UploadMedia(args.req_id, args.media_types, args.medium, args.carrier)
  File "MediaFilterService.py", line 91, in UploadMedia
    _return = self._predict(base64_images, ImageSize)
  File "MediaFilterService.py", line 67, in _predict
    images.append(self._load_base64_image(img, image_size))
  File "MediaFilterService.py", line 42, in _load_base64_image
    image = Image.open(tempBuff)
  File "/usr/local/lib/python2.7/dist-packages/PIL/Image.py", line 2818, in open
    raise IOError("cannot identify image file %r" % (filename if filename else fp))
IOError: cannot identify image file <StringIO.StringIO instance at 0x7f262c01deb0>
ERROR:root:Unexpected exception in handler
Traceback (most recent call last):
  File "../../gen-py/social_network/MediaFilterService.py", line 109, in process_UploadMedia
    result.success = self._handler.UploadMedia(args.req_id, args.media_types, args.medium, args.carrier)
  File "MediaFilterService.py", line 91, in UploadMedia
    _return = self._predict(base64_images, ImageSize)
  File "MediaFilterService.py", line 67, in _predict
    images.append(self._load_base64_image(img, image_size))
  File "MediaFilterService.py", line 44, in _load_base64_image
    image = image.convert('RGB')
  File "/usr/local/lib/python2.7/dist-packages/PIL/Image.py", line 930, in convert
    self.load()
  File "/usr/local/lib/python2.7/dist-packages/PIL/ImageFile.py", line 272, in load
    raise_ioerror(err_code)
  File "/usr/local/lib/python2.7/dist-packages/PIL/ImageFile.py", line 59, in raise_ioerror
    raise IOError(message + " when reading image file")
IOError: broken data stream when reading image file
ERROR:root:Unexpected exception in handler
Traceback (most recent call last):
  File "../../gen-py/social_network/MediaFilterService.py", line 109, in process_UploadMedia
    result.success = self._handler.UploadMedia(args.req_id, args.media_types, args.medium, args.carrier)
  File "MediaFilterService.py", line 91, in UploadMedia
    _return = self._predict(base64_images, ImageSize)
  File "MediaFilterService.py", line 67, in _predict
    images.append(self._load_base64_image(img, image_size))
  File "MediaFilterService.py", line 38, in _load_base64_image
    img_str = base64.b64decode(base64_str)
  File "/usr/lib/python2.7/base64.py", line 78, in b64decode
    raise TypeError(msg)
TypeError: Incorrect padding
ERROR:root:Unexpected exception in handler
Traceback (most recent call last):
  File "../../gen-py/social_network/MediaFilterService.py", line 109, in process_UploadMedia
    result.success = self._handler.UploadMedia(args.req_id, args.media_types, args.medium, args.carrier)
  File "MediaFilterService.py", line 91, in UploadMedia
    _return = self._predict(base64_images, ImageSize)
  File "MediaFilterService.py", line 67, in _predict
    images.append(self._load_base64_image(img, image_size))
  File "MediaFilterService.py", line 42, in _load_base64_image
    image = Image.open(tempBuff)
  File "/usr/local/lib/python2.7/dist-packages/PIL/Image.py", line 2818, in open
    raise IOError("cannot identify image file %r" % (filename if filename else fp))
IOError: cannot identify image file <StringIO.StringIO instance at 0x7f262c0c6dc0>
ERROR:root:Unexpected exception in handler
Traceback (most recent call last):
  File "../../gen-py/social_network/MediaFilterService.py", line 109, in process_UploadMedia
    result.success = self._handler.UploadMedia(args.req_id, args.media_types, args.medium, args.carrier)
  File "MediaFilterService.py", line 91, in UploadMedia
    _return = self._predict(base64_images, ImageSize)
  File "MediaFilterService.py", line 67, in _predict
    images.append(self._load_base64_image(img, image_size))
  File "MediaFilterService.py", line 45, in _load_base64_image
    image = image.resize(image_size)
  File "/usr/local/lib/python2.7/dist-packages/PIL/Image.py", line 1886, in resize
    self.load()
  File "/usr/local/lib/python2.7/dist-packages/PIL/ImageFile.py", line 272, in load
    raise_ioerror(err_code)
  File "/usr/local/lib/python2.7/dist-packages/PIL/ImageFile.py", line 59, in raise_ioerror
    raise IOError(message + " when reading image file")
IOError: broken data stream when reading image file
ERROR:root:Unexpected exception in handler
Traceback (most recent call last):
  File "../../gen-py/social_network/MediaFilterService.py", line 109, in process_UploadMedia
    result.success = self._handler.UploadMedia(args.req_id, args.media_types, args.medium, args.carrier)
  File "MediaFilterService.py", line 91, in UploadMedia
    _return = self._predict(base64_images, ImageSize)
  File "MediaFilterService.py", line 67, in _predict
    images.append(self._load_base64_image(img, image_size))
  File "MediaFilterService.py", line 38, in _load_base64_image
    img_str = base64.b64decode(base64_str)
  File "/usr/lib/python2.7/base64.py", line 78, in b64decode
    raise TypeError(msg)
TypeError: Incorrect padding
ERROR:root:Unexpected exception in handler
Traceback (most recent call last):
  File "../../gen-py/social_network/MediaFilterService.py", line 109, in process_UploadMedia
    result.success = self._handler.UploadMedia(args.req_id, args.media_types, args.medium, args.carrier)
  File "MediaFilterService.py", line 91, in UploadMedia
    _return = self._predict(base64_images, ImageSize)
  File "MediaFilterService.py", line 67, in _predict
    images.append(self._load_base64_image(img, image_size))
  File "MediaFilterService.py", line 38, in _load_base64_image
    img_str = base64.b64decode(base64_str)
  File "/usr/lib/python2.7/base64.py", line 78, in b64decode
    raise TypeError(msg)
TypeError: Incorrect padding
ERROR:root:Unexpected exception in handler
Traceback (most recent call last):
  File "../../gen-py/social_network/MediaFilterService.py", line 109, in process_UploadMedia
    result.success = self._handler.UploadMedia(args.req_id, args.media_types, args.medium, args.carrier)
  File "MediaFilterService.py", line 91, in UploadMedia
    _return = self._predict(base64_images, ImageSize)
  File "MediaFilterService.py", line 67, in _predict
    images.append(self._load_base64_image(img, image_size))
  File "MediaFilterService.py", line 42, in _load_base64_image
    image = Image.open(tempBuff)
  File "/usr/local/lib/python2.7/dist-packages/PIL/Image.py", line 2818, in open
    raise IOError("cannot identify image file %r" % (filename if filename else fp))
IOError: cannot identify image file <StringIO.StringIO instance at 0x7f27e8b0a9b0>
ERROR:root:Unexpected exception in handler
Traceback (most recent call last):
  File "../../gen-py/social_network/MediaFilterService.py", line 109, in process_UploadMedia
    result.success = self._handler.UploadMedia(args.req_id, args.media_types, args.medium, args.carrier)
  File "MediaFilterService.py", line 91, in UploadMedia
    _return = self._predict(base64_images, ImageSize)
  File "MediaFilterService.py", line 67, in _predict
    images.append(self._load_base64_image(img, image_size))
  File "MediaFilterService.py", line 38, in _load_base64_image
    img_str = base64.b64decode(base64_str)
  File "/usr/lib/python2.7/base64.py", line 78, in b64decode
    raise TypeError(msg)
TypeError: Incorrect padding
ERROR:root:Unexpected exception in handler
Traceback (most recent call last):
  File "../../gen-py/social_network/MediaFilterService.py", line 109, in process_UploadMedia
    result.success = self._handler.UploadMedia(args.req_id, args.media_types, args.medium, args.carrier)
  File "MediaFilterService.py", line 91, in UploadMedia
    _return = self._predict(base64_images, ImageSize)
  File "MediaFilterService.py", line 67, in _predict
    images.append(self._load_base64_image(img, image_size))
  File "MediaFilterService.py", line 42, in _load_base64_image
    image = Image.open(tempBuff)
  File "/usr/local/lib/python2.7/dist-packages/PIL/Image.py", line 2818, in open
    raise IOError("cannot identify image file %r" % (filename if filename else fp))
IOError: cannot identify image file <StringIO.StringIO instance at 0x7f262c0c6dc0>
ERROR:root:Unexpected exception in handler
Traceback (most recent call last):
  File "../../gen-py/social_network/MediaFilterService.py", line 109, in process_UploadMedia
    result.success = self._handler.UploadMedia(args.req_id, args.media_types, args.medium, args.carrier)
  File "MediaFilterService.py", line 91, in UploadMedia
    _return = self._predict(base64_images, ImageSize)
  File "MediaFilterService.py", line 67, in _predict
    images.append(self._load_base64_image(img, image_size))
  File "MediaFilterService.py", line 44, in _load_base64_image
    image = image.convert('RGB')
  File "/usr/local/lib/python2.7/dist-packages/PIL/Image.py", line 930, in convert
    self.load()
  File "/usr/local/lib/python2.7/dist-packages/PIL/ImageFile.py", line 272, in load
    raise_ioerror(err_code)
  File "/usr/local/lib/python2.7/dist-packages/PIL/ImageFile.py", line 59, in raise_ioerror
    raise IOError(message + " when reading image file")
IOError: broken data stream when reading image file
ERROR:root:Unexpected exception in handler
Traceback (most recent call last):
  File "../../gen-py/social_network/MediaFilterService.py", line 109, in process_UploadMedia
    result.success = self._handler.UploadMedia(args.req_id, args.media_types, args.medium, args.carrier)
  File "MediaFilterService.py", line 91, in UploadMedia
    _return = self._predict(base64_images, ImageSize)
  File "MediaFilterService.py", line 67, in _predict
    images.append(self._load_base64_image(img, image_size))
  File "MediaFilterService.py", line 38, in _load_base64_image
    img_str = base64.b64decode(base64_str)
  File "/usr/lib/python2.7/base64.py", line 78, in b64decode
    raise TypeError(msg)
TypeError: Incorrect padding
ERROR:root:Unexpected exception in handler
Traceback (most recent call last):
  File "../../gen-py/social_network/MediaFilterService.py", line 109, in process_UploadMedia
    result.success = self._handler.UploadMedia(args.req_id, args.media_types, args.medium, args.carrier)
  File "MediaFilterService.py", line 91, in UploadMedia
    _return = self._predict(base64_images, ImageSize)
  File "MediaFilterService.py", line 67, in _predict
    images.append(self._load_base64_image(img, image_size))
  File "MediaFilterService.py", line 38, in _load_base64_image
    img_str = base64.b64decode(base64_str)
  File "/usr/lib/python2.7/base64.py", line 78, in b64decode
    raise TypeError(msg)
TypeError: Incorrect padding
ERROR:root:Unexpected exception in handler
Traceback (most recent call last):
  File "../../gen-py/social_network/MediaFilterService.py", line 109, in process_UploadMedia
    result.success = self._handler.UploadMedia(args.req_id, args.media_types, args.medium, args.carrier)
  File "MediaFilterService.py", line 91, in UploadMedia
    _return = self._predict(base64_images, ImageSize)
  File "MediaFilterService.py", line 67, in _predict
    images.append(self._load_base64_image(img, image_size))
  File "MediaFilterService.py", line 38, in _load_base64_image
    img_str = base64.b64decode(base64_str)
  File "/usr/lib/python2.7/base64.py", line 78, in b64decode
    raise TypeError(msg)
TypeError: Incorrect padding
ERROR:root:Unexpected exception in handler
Traceback (most recent call last):
  File "../../gen-py/social_network/MediaFilterService.py", line 109, in process_UploadMedia
    result.success = self._handler.UploadMedia(args.req_id, args.media_types, args.medium, args.carrier)
  File "MediaFilterService.py", line 91, in UploadMedia
    _return = self._predict(base64_images, ImageSize)
  File "MediaFilterService.py", line 67, in _predict
    images.append(self._load_base64_image(img, image_size))
  File "MediaFilterService.py", line 38, in _load_base64_image
    img_str = base64.b64decode(base64_str)
  File "/usr/lib/python2.7/base64.py", line 78, in b64decode
    raise TypeError(msg)
TypeError: Incorrect padding
ERROR:root:Unexpected exception in handler
Traceback (most recent call last):
  File "../../gen-py/social_network/MediaFilterService.py", line 109, in process_UploadMedia
    result.success = self._handler.UploadMedia(args.req_id, args.media_types, args.medium, args.carrier)
  File "MediaFilterService.py", line 91, in UploadMedia
    _return = self._predict(base64_images, ImageSize)
  File "MediaFilterService.py", line 67, in _predict
    images.append(self._load_base64_image(img, image_size))
  File "MediaFilterService.py", line 38, in _load_base64_image
    img_str = base64.b64decode(base64_str)
  File "/usr/lib/python2.7/base64.py", line 78, in b64decode
    raise TypeError(msg)
TypeError: Incorrect padding
ERROR:root:Unexpected exception in handler
Traceback (most recent call last):
  File "../../gen-py/social_network/MediaFilterService.py", line 109, in process_UploadMedia
    result.success = self._handler.UploadMedia(args.req_id, args.media_types, args.medium, args.carrier)
  File "MediaFilterService.py", line 91, in UploadMedia
    _return = self._predict(base64_images, ImageSize)
  File "MediaFilterService.py", line 67, in _predict
    images.append(self._load_base64_image(img, image_size))
  File "MediaFilterService.py", line 38, in _load_base64_image
    img_str = base64.b64decode(base64_str)
  File "/usr/lib/python2.7/base64.py", line 78, in b64decode
    raise TypeError(msg)
TypeError: Incorrect padding
ERROR:root:Unexpected exception in handler
Traceback (most recent call last):
  File "../../gen-py/social_network/MediaFilterService.py", line 109, in process_UploadMedia
    result.success = self._handler.UploadMedia(args.req_id, args.media_types, args.medium, args.carrier)
  File "MediaFilterService.py", line 91, in UploadMedia
    _return = self._predict(base64_images, ImageSize)
  File "MediaFilterService.py", line 67, in _predict
    images.append(self._load_base64_image(img, image_size))
  File "MediaFilterService.py", line 45, in _load_base64_image
    image = image.resize(image_size)
  File "/usr/local/lib/python2.7/dist-packages/PIL/Image.py", line 1886, in resize
    self.load()
  File "/usr/local/lib/python2.7/dist-packages/PIL/ImageFile.py", line 272, in load
    raise_ioerror(err_code)
  File "/usr/local/lib/python2.7/dist-packages/PIL/ImageFile.py", line 59, in raise_ioerror
    raise IOError(message + " when reading image file")
IOError: broken data stream when reading image file
ERROR:root:Unexpected exception in handler
Traceback (most recent call last):
  File "../../gen-py/social_network/MediaFilterService.py", line 109, in process_UploadMedia
    result.success = self._handler.UploadMedia(args.req_id, args.media_types, args.medium, args.carrier)
  File "MediaFilterService.py", line 91, in UploadMedia
    _return = self._predict(base64_images, ImageSize)
  File "MediaFilterService.py", line 67, in _predict
    images.append(self._load_base64_image(img, image_size))
  File "MediaFilterService.py", line 42, in _load_base64_image
    image = Image.open(tempBuff)
  File "/usr/local/lib/python2.7/dist-packages/PIL/Image.py", line 2818, in open
    raise IOError("cannot identify image file %r" % (filename if filename else fp))
IOError: cannot identify image file <StringIO.StringIO instance at 0x7f26742b9c30>
ERROR:root:Unexpected exception in handler
Traceback (most recent call last):
  File "../../gen-py/social_network/MediaFilterService.py", line 109, in process_UploadMedia
    result.success = self._handler.UploadMedia(args.req_id, args.media_types, args.medium, args.carrier)
  File "MediaFilterService.py", line 91, in UploadMedia
    _return = self._predict(base64_images, ImageSize)
  File "MediaFilterService.py", line 67, in _predict
    images.append(self._load_base64_image(img, image_size))
  File "MediaFilterService.py", line 42, in _load_base64_image
    image = Image.open(tempBuff)
  File "/usr/local/lib/python2.7/dist-packages/PIL/Image.py", line 2818, in open
    raise IOError("cannot identify image file %r" % (filename if filename else fp))
IOError: cannot identify image file <StringIO.StringIO instance at 0x7f267470ce60>
ERROR:root:Unexpected exception in handler
Traceback (most recent call last):
  File "../../gen-py/social_network/MediaFilterService.py", line 109, in process_UploadMedia
    result.success = self._handler.UploadMedia(args.req_id, args.media_types, args.medium, args.carrier)
  File "MediaFilterService.py", line 91, in UploadMedia
    _return = self._predict(base64_images, ImageSize)
  File "MediaFilterService.py", line 67, in _predict
    images.append(self._load_base64_image(img, image_size))
  File "MediaFilterService.py", line 45, in _load_base64_image
    image = image.resize(image_size)
  File "/usr/local/lib/python2.7/dist-packages/PIL/Image.py", line 1886, in resize
    self.load()
  File "/usr/local/lib/python2.7/dist-packages/PIL/ImageFile.py", line 272, in load
    raise_ioerror(err_code)
  File "/usr/local/lib/python2.7/dist-packages/PIL/ImageFile.py", line 59, in raise_ioerror
    raise IOError(message + " when reading image file")
IOError: broken data stream when reading image file
ERROR:root:Unexpected exception in handler
Traceback (most recent call last):
  File "../../gen-py/social_network/MediaFilterService.py", line 109, in process_UploadMedia
    result.success = self._handler.UploadMedia(args.req_id, args.media_types, args.medium, args.carrier)
  File "MediaFilterService.py", line 91, in UploadMedia
    _return = self._predict(base64_images, ImageSize)
  File "MediaFilterService.py", line 67, in _predict
    images.append(self._load_base64_image(img, image_size))
  File "MediaFilterService.py", line 42, in _load_base64_image
    image = Image.open(tempBuff)
  File "/usr/local/lib/python2.7/dist-packages/PIL/Image.py", line 2818, in open
    raise IOError("cannot identify image file %r" % (filename if filename else fp))
IOError: cannot identify image file <StringIO.StringIO instance at 0x7f262c0a9eb0>
ERROR:root:Unexpected exception in handler
Traceback (most recent call last):
  File "../../gen-py/social_network/MediaFilterService.py", line 109, in process_UploadMedia
    result.success = self._handler.UploadMedia(args.req_id, args.media_types, args.medium, args.carrier)
  File "MediaFilterService.py", line 91, in UploadMedia
    _return = self._predict(base64_images, ImageSize)
  File "MediaFilterService.py", line 67, in _predict
    images.append(self._load_base64_image(img, image_size))
  File "MediaFilterService.py", line 44, in _load_base64_image
    image = image.convert('RGB')
  File "/usr/local/lib/python2.7/dist-packages/PIL/Image.py", line 930, in convert
    self.load()
  File "/usr/local/lib/python2.7/dist-packages/PIL/ImageFile.py", line 272, in load
    raise_ioerror(err_code)
  File "/usr/local/lib/python2.7/dist-packages/PIL/ImageFile.py", line 59, in raise_ioerror
    raise IOError(message + " when reading image file")
IOError: unrecognized data stream contents when reading image file
ERROR:root:Unexpected exception in handler
Traceback (most recent call last):
  File "../../gen-py/social_network/MediaFilterService.py", line 109, in process_UploadMedia
    result.success = self._handler.UploadMedia(args.req_id, args.media_types, args.medium, args.carrier)
  File "MediaFilterService.py", line 91, in UploadMedia
    _return = self._predict(base64_images, ImageSize)
  File "MediaFilterService.py", line 67, in _predict
    images.append(self._load_base64_image(img, image_size))
  File "MediaFilterService.py", line 38, in _load_base64_image
    img_str = base64.b64decode(base64_str)
  File "/usr/lib/python2.7/base64.py", line 78, in b64decode
    raise TypeError(msg)
TypeError: Incorrect padding
ERROR:root:Unexpected exception in handler
Traceback (most recent call last):
  File "../../gen-py/social_network/MediaFilterService.py", line 109, in process_UploadMedia
    result.success = self._handler.UploadMedia(args.req_id, args.media_types, args.medium, args.carrier)
  File "MediaFilterService.py", line 91, in UploadMedia
    _return = self._predict(base64_images, ImageSize)
  File "MediaFilterService.py", line 67, in _predict
    images.append(self._load_base64_image(img, image_size))
  File "MediaFilterService.py", line 44, in _load_base64_image
    image = image.convert('RGB')
  File "/usr/local/lib/python2.7/dist-packages/PIL/Image.py", line 930, in convert
    self.load()
  File "/usr/local/lib/python2.7/dist-packages/PIL/ImageFile.py", line 272, in load
    raise_ioerror(err_code)
  File "/usr/local/lib/python2.7/dist-packages/PIL/ImageFile.py", line 59, in raise_ioerror
    raise IOError(message + " when reading image file")
IOError: unrecognized data stream contents when reading image file
